[2024-04-11T16:10:55.857+0000] {local_task_job_runner.py:120} INFO - ::group::Pre task execution logs
[2024-04-11T16:10:55.895+0000] {taskinstance.py:2073} INFO - Dependencies all met for dep_context=non-requeueable deps ti=<TaskInstance: Process_W3_Data.insert_data_into_db manual__2024-04-11T16:10:14.516216+00:00 [queued]>
[2024-04-11T16:10:55.906+0000] {taskinstance.py:2073} INFO - Dependencies all met for dep_context=requeueable deps ti=<TaskInstance: Process_W3_Data.insert_data_into_db manual__2024-04-11T16:10:14.516216+00:00 [queued]>
[2024-04-11T16:10:55.907+0000] {taskinstance.py:2303} INFO - Starting attempt 1 of 1
[2024-04-11T16:10:55.924+0000] {taskinstance.py:2327} INFO - Executing <Task(PythonOperator): insert_data_into_db> on 2024-04-11 16:10:14.516216+00:00
[2024-04-11T16:10:55.935+0000] {warnings.py:110} WARNING - /home/***/.local/lib/python3.12/site-packages/***/task/task_runner/standard_task_runner.py:61: DeprecationWarning: This process (pid=22200) is multi-threaded, use of fork() may lead to deadlocks in the child.
  pid = os.fork()

[2024-04-11T16:10:55.939+0000] {standard_task_runner.py:63} INFO - Started process 22202 to run task
[2024-04-11T16:10:55.939+0000] {standard_task_runner.py:90} INFO - Running: ['***', 'tasks', 'run', 'Process_W3_Data', 'insert_data_into_db', 'manual__2024-04-11T16:10:14.516216+00:00', '--job-id', '132', '--raw', '--subdir', 'DAGS_FOLDER/w3c.py', '--cfg-path', '/tmp/tmp4uq9qyyi']
[2024-04-11T16:10:55.943+0000] {standard_task_runner.py:91} INFO - Job 132: Subtask insert_data_into_db
[2024-04-11T16:10:56.008+0000] {task_command.py:426} INFO - Running <TaskInstance: Process_W3_Data.insert_data_into_db manual__2024-04-11T16:10:14.516216+00:00 [running]> on host 426f0b9f9d71
[2024-04-11T16:10:56.122+0000] {taskinstance.py:2644} INFO - Exporting env vars: AIRFLOW_CTX_DAG_OWNER='***' AIRFLOW_CTX_DAG_ID='Process_W3_Data' AIRFLOW_CTX_TASK_ID='insert_data_into_db' AIRFLOW_CTX_EXECUTION_DATE='2024-04-11T16:10:14.516216+00:00' AIRFLOW_CTX_TRY_NUMBER='1' AIRFLOW_CTX_DAG_RUN_ID='manual__2024-04-11T16:10:14.516216+00:00'
[2024-04-11T16:10:56.125+0000] {taskinstance.py:430} INFO - ::endgroup::
[2024-04-11T16:10:56.137+0000] {base.py:84} INFO - Using connection ID 'postgres_default' for task execution.
[2024-04-11T16:10:56.193+0000] {logging_mixin.py:188} INFO - Total lines read: 89816
[2024-04-11T16:10:56.193+0000] {taskinstance.py:441} INFO - ::group::Post task execution logs
[2024-04-11T16:10:56.194+0000] {taskinstance.py:2890} ERROR - Task failed with exception
Traceback (most recent call last):
  File "/home/airflow/.local/lib/python3.12/site-packages/airflow/models/taskinstance.py", line 465, in _execute_task
    result = _execute_callable(context=context, **execute_callable_kwargs)
             ^^^^^^^^^^^^^^^^^^^^^^^^^^^^^^^^^^^^^^^^^^^^^^^^^^^^^^^^^^^^^
  File "/home/airflow/.local/lib/python3.12/site-packages/airflow/models/taskinstance.py", line 432, in _execute_callable
    return execute_callable(context=context, **execute_callable_kwargs)
           ^^^^^^^^^^^^^^^^^^^^^^^^^^^^^^^^^^^^^^^^^^^^^^^^^^^^^^^^^^^^
  File "/home/airflow/.local/lib/python3.12/site-packages/airflow/models/baseoperator.py", line 400, in wrapper
    return func(self, *args, **kwargs)
           ^^^^^^^^^^^^^^^^^^^^^^^^^^^
  File "/home/airflow/.local/lib/python3.12/site-packages/airflow/operators/python.py", line 235, in execute
    return_value = self.execute_callable()
                   ^^^^^^^^^^^^^^^^^^^^^^^
  File "/home/airflow/.local/lib/python3.12/site-packages/airflow/operators/python.py", line 252, in execute_callable
    return self.python_callable(*self.op_args, **self.op_kwargs)
           ^^^^^^^^^^^^^^^^^^^^^^^^^^^^^^^^^^^^^^^^^^^^^^^^^^^^^
  File "/opt/airflow/dags/w3c.py", line 73, in insert_data_into_db
    next(file)  # Skip the header row
    ^^^^^^^^^^
StopIteration
[2024-04-11T16:10:56.207+0000] {taskinstance.py:1205} INFO - Marking task as FAILED. dag_id=Process_W3_Data, task_id=insert_data_into_db, execution_date=20240411T161014, start_date=20240411T161055, end_date=20240411T161056
[2024-04-11T16:10:56.223+0000] {standard_task_runner.py:110} ERROR - Failed to execute job 132 for task insert_data_into_db (; 22202)
[2024-04-11T16:10:56.238+0000] {local_task_job_runner.py:240} INFO - Task exited with return code 1
[2024-04-11T16:10:56.261+0000] {taskinstance.py:3482} INFO - 0 downstream tasks scheduled from follow-on schedule check
[2024-04-11T16:10:56.263+0000] {local_task_job_runner.py:222} INFO - ::endgroup::
