[2024-04-11T15:23:55.238+0000] {local_task_job_runner.py:120} INFO - ::group::Pre task execution logs
[2024-04-11T15:23:55.348+0000] {taskinstance.py:2073} INFO - Dependencies all met for dep_context=non-requeueable deps ti=<TaskInstance: Process_W3_Data.insert_data_into_db manual__2024-04-11T15:23:47.460351+00:00 [queued]>
[2024-04-11T15:23:55.379+0000] {taskinstance.py:2073} INFO - Dependencies all met for dep_context=requeueable deps ti=<TaskInstance: Process_W3_Data.insert_data_into_db manual__2024-04-11T15:23:47.460351+00:00 [queued]>
[2024-04-11T15:23:55.379+0000] {taskinstance.py:2303} INFO - Starting attempt 1 of 1
[2024-04-11T15:23:55.430+0000] {taskinstance.py:2327} INFO - Executing <Task(PythonOperator): insert_data_into_db> on 2024-04-11 15:23:47.460351+00:00
[2024-04-11T15:23:55.450+0000] {warnings.py:110} WARNING - /home/***/.local/lib/python3.12/site-packages/***/task/task_runner/standard_task_runner.py:61: DeprecationWarning: This process (pid=21342) is multi-threaded, use of fork() may lead to deadlocks in the child.
  pid = os.fork()

[2024-04-11T15:23:55.468+0000] {standard_task_runner.py:63} INFO - Started process 21353 to run task
[2024-04-11T15:23:55.465+0000] {standard_task_runner.py:90} INFO - Running: ['***', 'tasks', 'run', 'Process_W3_Data', 'insert_data_into_db', 'manual__2024-04-11T15:23:47.460351+00:00', '--job-id', '54', '--raw', '--subdir', 'DAGS_FOLDER/w3c.py', '--cfg-path', '/tmp/tmp6dvsbw3f']
[2024-04-11T15:23:55.484+0000] {standard_task_runner.py:91} INFO - Job 54: Subtask insert_data_into_db
[2024-04-11T15:23:55.638+0000] {task_command.py:426} INFO - Running <TaskInstance: Process_W3_Data.insert_data_into_db manual__2024-04-11T15:23:47.460351+00:00 [running]> on host 426f0b9f9d71
[2024-04-11T15:23:56.041+0000] {taskinstance.py:2644} INFO - Exporting env vars: AIRFLOW_CTX_DAG_OWNER='***' AIRFLOW_CTX_DAG_ID='Process_W3_Data' AIRFLOW_CTX_TASK_ID='insert_data_into_db' AIRFLOW_CTX_EXECUTION_DATE='2024-04-11T15:23:47.460351+00:00' AIRFLOW_CTX_TRY_NUMBER='1' AIRFLOW_CTX_DAG_RUN_ID='manual__2024-04-11T15:23:47.460351+00:00'
[2024-04-11T15:23:56.045+0000] {taskinstance.py:430} INFO - ::endgroup::
[2024-04-11T15:23:56.083+0000] {taskinstance.py:441} INFO - ::group::Post task execution logs
[2024-04-11T15:23:56.119+0000] {taskinstance.py:2890} ERROR - Task failed with exception
Traceback (most recent call last):
  File "/home/airflow/.local/lib/python3.12/site-packages/airflow/models/taskinstance.py", line 465, in _execute_task
    result = _execute_callable(context=context, **execute_callable_kwargs)
             ^^^^^^^^^^^^^^^^^^^^^^^^^^^^^^^^^^^^^^^^^^^^^^^^^^^^^^^^^^^^^
  File "/home/airflow/.local/lib/python3.12/site-packages/airflow/models/taskinstance.py", line 432, in _execute_callable
    return execute_callable(context=context, **execute_callable_kwargs)
           ^^^^^^^^^^^^^^^^^^^^^^^^^^^^^^^^^^^^^^^^^^^^^^^^^^^^^^^^^^^^
  File "/home/airflow/.local/lib/python3.12/site-packages/airflow/models/baseoperator.py", line 400, in wrapper
    return func(self, *args, **kwargs)
           ^^^^^^^^^^^^^^^^^^^^^^^^^^^
  File "/home/airflow/.local/lib/python3.12/site-packages/airflow/operators/python.py", line 235, in execute
    return_value = self.execute_callable()
                   ^^^^^^^^^^^^^^^^^^^^^^^
  File "/home/airflow/.local/lib/python3.12/site-packages/airflow/operators/python.py", line 252, in execute_callable
    return self.python_callable(*self.op_args, **self.op_kwargs)
           ^^^^^^^^^^^^^^^^^^^^^^^^^^^^^^^^^^^^^^^^^^^^^^^^^^^^^
  File "/opt/airflow/dags/w3c.py", line 58, in insert_data_into_db
    conn = pg_hook.get_conn()
           ^^^^^^^^^^^^^^^^^^
  File "/home/airflow/.local/lib/python3.12/site-packages/airflow/providers/postgres/hooks/postgres.py", line 131, in get_conn
    conn = deepcopy(self.connection or self.get_connection(conn_id))
                                       ^^^^^^^^^^^^^^^^^^^^^^^^^^^^
  File "/home/airflow/.local/lib/python3.12/site-packages/airflow/hooks/base.py", line 83, in get_connection
    conn = Connection.get_connection_from_secrets(conn_id)
           ^^^^^^^^^^^^^^^^^^^^^^^^^^^^^^^^^^^^^^^^^^^^^^^
  File "/home/airflow/.local/lib/python3.12/site-packages/airflow/models/connection.py", line 519, in get_connection_from_secrets
    raise AirflowNotFoundException(f"The conn_id `{conn_id}` isn't defined")
airflow.exceptions.AirflowNotFoundException: The conn_id `your_connection_id_here` isn't defined
[2024-04-11T15:23:56.158+0000] {taskinstance.py:1205} INFO - Marking task as FAILED. dag_id=Process_W3_Data, task_id=insert_data_into_db, execution_date=20240411T152347, start_date=20240411T152355, end_date=20240411T152356
[2024-04-11T15:23:56.218+0000] {standard_task_runner.py:110} ERROR - Failed to execute job 54 for task insert_data_into_db (The conn_id `your_connection_id_here` isn't defined; 21353)
[2024-04-11T15:23:56.297+0000] {local_task_job_runner.py:240} INFO - Task exited with return code 1
[2024-04-11T15:23:56.380+0000] {taskinstance.py:3482} INFO - 0 downstream tasks scheduled from follow-on schedule check
[2024-04-11T15:23:56.388+0000] {local_task_job_runner.py:222} INFO - ::endgroup::
