[2024-04-11T15:39:47.410+0000] {local_task_job_runner.py:120} INFO - ::group::Pre task execution logs
[2024-04-11T15:39:47.481+0000] {taskinstance.py:2073} INFO - Dependencies all met for dep_context=non-requeueable deps ti=<TaskInstance: Process_W3_Data.insert_data_into_db manual__2024-04-11T15:39:42.458503+00:00 [queued]>
[2024-04-11T15:39:47.505+0000] {taskinstance.py:2073} INFO - Dependencies all met for dep_context=requeueable deps ti=<TaskInstance: Process_W3_Data.insert_data_into_db manual__2024-04-11T15:39:42.458503+00:00 [queued]>
[2024-04-11T15:39:47.506+0000] {taskinstance.py:2303} INFO - Starting attempt 1 of 1
[2024-04-11T15:39:47.550+0000] {taskinstance.py:2327} INFO - Executing <Task(PythonOperator): insert_data_into_db> on 2024-04-11 15:39:42.458503+00:00
[2024-04-11T15:39:47.580+0000] {warnings.py:110} WARNING - /home/***/.local/lib/python3.12/site-packages/***/task/task_runner/standard_task_runner.py:61: DeprecationWarning: This process (pid=21650) is multi-threaded, use of fork() may lead to deadlocks in the child.
  pid = os.fork()

[2024-04-11T15:39:47.583+0000] {standard_task_runner.py:63} INFO - Started process 21654 to run task
[2024-04-11T15:39:47.595+0000] {standard_task_runner.py:90} INFO - Running: ['***', 'tasks', 'run', 'Process_W3_Data', 'insert_data_into_db', 'manual__2024-04-11T15:39:42.458503+00:00', '--job-id', '84', '--raw', '--subdir', 'DAGS_FOLDER/w3c.py', '--cfg-path', '/tmp/tmpps8qwpno']
[2024-04-11T15:39:47.608+0000] {standard_task_runner.py:91} INFO - Job 84: Subtask insert_data_into_db
[2024-04-11T15:39:47.763+0000] {task_command.py:426} INFO - Running <TaskInstance: Process_W3_Data.insert_data_into_db manual__2024-04-11T15:39:42.458503+00:00 [running]> on host 426f0b9f9d71
[2024-04-11T15:39:48.085+0000] {taskinstance.py:2644} INFO - Exporting env vars: AIRFLOW_CTX_DAG_OWNER='***' AIRFLOW_CTX_DAG_ID='Process_W3_Data' AIRFLOW_CTX_TASK_ID='insert_data_into_db' AIRFLOW_CTX_EXECUTION_DATE='2024-04-11T15:39:42.458503+00:00' AIRFLOW_CTX_TRY_NUMBER='1' AIRFLOW_CTX_DAG_RUN_ID='manual__2024-04-11T15:39:42.458503+00:00'
[2024-04-11T15:39:48.089+0000] {taskinstance.py:430} INFO - ::endgroup::
[2024-04-11T15:39:48.124+0000] {base.py:84} INFO - Using connection ID 'postgres_default' for task execution.
[2024-04-11T15:39:48.137+0000] {taskinstance.py:441} INFO - ::group::Post task execution logs
[2024-04-11T15:39:48.137+0000] {taskinstance.py:2890} ERROR - Task failed with exception
Traceback (most recent call last):
  File "/home/airflow/.local/lib/python3.12/site-packages/airflow/models/taskinstance.py", line 465, in _execute_task
    result = _execute_callable(context=context, **execute_callable_kwargs)
             ^^^^^^^^^^^^^^^^^^^^^^^^^^^^^^^^^^^^^^^^^^^^^^^^^^^^^^^^^^^^^
  File "/home/airflow/.local/lib/python3.12/site-packages/airflow/models/taskinstance.py", line 432, in _execute_callable
    return execute_callable(context=context, **execute_callable_kwargs)
           ^^^^^^^^^^^^^^^^^^^^^^^^^^^^^^^^^^^^^^^^^^^^^^^^^^^^^^^^^^^^
  File "/home/airflow/.local/lib/python3.12/site-packages/airflow/models/baseoperator.py", line 400, in wrapper
    return func(self, *args, **kwargs)
           ^^^^^^^^^^^^^^^^^^^^^^^^^^^
  File "/home/airflow/.local/lib/python3.12/site-packages/airflow/operators/python.py", line 235, in execute
    return_value = self.execute_callable()
                   ^^^^^^^^^^^^^^^^^^^^^^^
  File "/home/airflow/.local/lib/python3.12/site-packages/airflow/operators/python.py", line 252, in execute_callable
    return self.python_callable(*self.op_args, **self.op_kwargs)
           ^^^^^^^^^^^^^^^^^^^^^^^^^^^^^^^^^^^^^^^^^^^^^^^^^^^^^
  File "/opt/airflow/dags/w3c.py", line 71, in insert_data_into_db
    cursor.copy_from(file, table_name, sep=',', null='')
psycopg2.errors.UndefinedTable: relation "your_table_name" does not exist

[2024-04-11T15:39:48.164+0000] {taskinstance.py:1205} INFO - Marking task as FAILED. dag_id=Process_W3_Data, task_id=insert_data_into_db, execution_date=20240411T153942, start_date=20240411T153947, end_date=20240411T153948
[2024-04-11T15:39:48.204+0000] {standard_task_runner.py:110} ERROR - Failed to execute job 84 for task insert_data_into_db (relation "your_table_name" does not exist
; 21654)
[2024-04-11T15:39:48.273+0000] {local_task_job_runner.py:240} INFO - Task exited with return code 1
[2024-04-11T15:39:48.325+0000] {taskinstance.py:3482} INFO - 0 downstream tasks scheduled from follow-on schedule check
[2024-04-11T15:39:48.328+0000] {local_task_job_runner.py:222} INFO - ::endgroup::
