[2024-04-11T16:03:41.074+0000] {local_task_job_runner.py:120} INFO - ::group::Pre task execution logs
[2024-04-11T16:03:41.102+0000] {taskinstance.py:2073} INFO - Dependencies all met for dep_context=non-requeueable deps ti=<TaskInstance: Process_W3_Data.insert_data_into_db manual__2024-04-11T16:03:00.871751+00:00 [queued]>
[2024-04-11T16:03:41.112+0000] {taskinstance.py:2073} INFO - Dependencies all met for dep_context=requeueable deps ti=<TaskInstance: Process_W3_Data.insert_data_into_db manual__2024-04-11T16:03:00.871751+00:00 [queued]>
[2024-04-11T16:03:41.112+0000] {taskinstance.py:2303} INFO - Starting attempt 1 of 1
[2024-04-11T16:03:41.131+0000] {taskinstance.py:2327} INFO - Executing <Task(PythonOperator): insert_data_into_db> on 2024-04-11 16:03:00.871751+00:00
[2024-04-11T16:03:41.141+0000] {warnings.py:110} WARNING - /home/***/.local/lib/python3.12/site-packages/***/task/task_runner/standard_task_runner.py:61: DeprecationWarning: This process (pid=22080) is multi-threaded, use of fork() may lead to deadlocks in the child.
  pid = os.fork()

[2024-04-11T16:03:41.144+0000] {standard_task_runner.py:63} INFO - Started process 22082 to run task
[2024-04-11T16:03:41.145+0000] {standard_task_runner.py:90} INFO - Running: ['***', 'tasks', 'run', 'Process_W3_Data', 'insert_data_into_db', 'manual__2024-04-11T16:03:00.871751+00:00', '--job-id', '122', '--raw', '--subdir', 'DAGS_FOLDER/w3c.py', '--cfg-path', '/tmp/tmpefzfozyk']
[2024-04-11T16:03:41.149+0000] {standard_task_runner.py:91} INFO - Job 122: Subtask insert_data_into_db
[2024-04-11T16:03:41.214+0000] {task_command.py:426} INFO - Running <TaskInstance: Process_W3_Data.insert_data_into_db manual__2024-04-11T16:03:00.871751+00:00 [running]> on host 426f0b9f9d71
[2024-04-11T16:03:41.363+0000] {taskinstance.py:2644} INFO - Exporting env vars: AIRFLOW_CTX_DAG_OWNER='***' AIRFLOW_CTX_DAG_ID='Process_W3_Data' AIRFLOW_CTX_TASK_ID='insert_data_into_db' AIRFLOW_CTX_EXECUTION_DATE='2024-04-11T16:03:00.871751+00:00' AIRFLOW_CTX_TRY_NUMBER='1' AIRFLOW_CTX_DAG_RUN_ID='manual__2024-04-11T16:03:00.871751+00:00'
[2024-04-11T16:03:41.366+0000] {taskinstance.py:430} INFO - ::endgroup::
[2024-04-11T16:03:41.377+0000] {base.py:84} INFO - Using connection ID 'postgres_default' for task execution.
[2024-04-11T16:03:41.834+0000] {logging_mixin.py:188} INFO - Error importing data: extra data after last expected column
CONTEXT:  COPY fact-table, line 89815: "2010-10-31,00:06:21,Mozilla/5.0+(compatible;+Yahoo!+Slurp;+http://help.yahoo.com/help/us/ysearch/slu..."
[2024-04-11T16:03:41.835+0000] {python.py:237} INFO - Done. Returned value was: None
[2024-04-11T16:03:41.837+0000] {taskinstance.py:441} INFO - ::group::Post task execution logs
[2024-04-11T16:03:41.852+0000] {taskinstance.py:1205} INFO - Marking task as SUCCESS. dag_id=Process_W3_Data, task_id=insert_data_into_db, execution_date=20240411T160300, start_date=20240411T160341, end_date=20240411T160341
[2024-04-11T16:03:41.885+0000] {local_task_job_runner.py:240} INFO - Task exited with return code 0
[2024-04-11T16:03:41.909+0000] {taskinstance.py:3482} INFO - 0 downstream tasks scheduled from follow-on schedule check
[2024-04-11T16:03:41.911+0000] {local_task_job_runner.py:222} INFO - ::endgroup::
